Workbook

Sheet README
A1: Elasticity ε — Monthly and Annual Comparative Analysis
A3: Item | B3: Definition / Method | C3: Unit | D3: Reference | E3: Important note | F3: Excel implementation
A4: Monthly grid import | B4: E_grid,m = Σ_t∈m E_grid,t | C4: kWh | D4: Column X: E_grid,t EQ2–EQ4 | E4: Sum of hourly grid imports by month. | F4: SUM of hourly grid-import values
A5: Monthly weighted purchase price | B5: P_m = Σ(P_t·E_grid,t) / ΣE_grid,t | C5: €/kWh | D5: Column L weighted by column X | E5: Hours with zero grid import receive zero weight. | F5: SUMPRODUCT(Price,GridImport)/SUM(GridImport)
A6: Monthly elasticity | B6: ε_m = (ΔE_grid,m / E_grid,m,prev) / (ΔP_m / P_m,prev) | C6: dimensionless | D6: Month-on-month aggregate elasticity | E6: January is blank because no previous month exists. | F6: ((E_m-E_prev)/E_prev)/((P_m-P_prev)/P_prev)
A7: Annual aggregate elasticity | B7: ε_annual = (ΔE_annual/E_ref) / (ΔP_annual/P_ref) | C7: dimensionless | D7: Reference scenario: Strategy A, 10 kWh | E7: The reference scenario itself is undefined (0/0) and is left blank. | F7: Scenario annual aggregate compared with A-10 kWh
A8: Annual weighted elasticity | B8: Σ(E_grid,m·ε_m) / ΣE_grid,m | C8: dimensionless | D8: Weighted summary of monthly aggregate elasticities | E8: Provided because only one calendar year is available; a true year-on-year elasticity requires at least two years. | F8: SUMPRODUCT(monthly E, monthly ε)/SUM(monthly E)
A9: Price input | B9: Price,spot,t | C9: €/kWh | D9: Source column L (converted from €/MWh in column J) | E9: Names and units follow the attached workbooks. | F9: Direct source aggregation
A10: Scenarios | B10: Strategies A, B, C × battery capacities 10, 15, 20, 30 kWh | C10: - | D10: 12 attached workbooks | E10: All tables and charts are editable native Excel objects. | F10: -

Sheet Monthly_Aggregates
A1: Monthly Aggregate Inputs for Elasticity Calculation
A3: Month | B3: A-10kWh E_grid,m (kWh) | C3: A-10kWh P_m weighted (€/kWh) | D3: A-15kWh E_grid,m (kWh) | E3: A-15kWh P_m weighted (€/kWh) | F3: A-20kWh E_grid,m (kWh) | G3: A-20kWh P_m weighted (€/kWh) | H3: A-30kWh E_grid,m (kWh) | I3: A-30kWh P_m weighted (€/kWh) | J3: B-10kWh E_grid,m (kWh) | K3: B-10kWh P_m weighted (€/kWh) | L3: B-15kWh E_grid,m (kWh) | M3: B-15kWh P_m weighted (€/kWh) | N3: B-20kWh E_grid,m (kWh) | O3: B-20kWh P_m weighted (€/kWh) | P3: B-30kWh E_grid,m (kWh) | Q3: B-30kWh P_m weighted (€/kWh) | R3: C-10kWh E_grid,m (kWh) | S3: C-10kWh P_m weighted (€/kWh) | T3: C-15kWh E_grid,m (kWh) | U3: C-15kWh P_m weighted (€/kWh) | V3: C-20kWh E_grid,m (kWh) | W3: C-20kWh P_m weighted (€/kWh) | X3: C-30kWh E_grid,m (kWh) | Y3: C-30kWh P_m weighted (€/kWh)
A4: Jan | B4: 149.72681 | C4: 0.12663697 | D4: 147.22353 | E4: 0.12618136 | F4: 147.22353 | G4: 0.12618136 | H4: 147.22353 | I4: 0.12618136 | J4: 196.84055 | K4: 0.13358585 | L4: 191.8987 | M4: 0.13160771 | N4: 186.12957 | O4: 0.13074563 | P4: 183.07772 | Q4: 0.13058735 | R4: 139.3275 | S4: 0.12376443 | T4: 133.72182 | U4: 0.1229699 | V4: 131.41045 | W4: 0.12274597 | X4: 127.77873 | Y4: 0.12224322
A5: Feb | B5: 146.86995 | C5: 0.15172386 | D5: 146.86995 | E5: 0.15172386 | F5: 146.86995 | G5: 0.15172386 | H5: 146.86995 | I5: 0.15172386 | J5: 172.06702 | K5: 0.15361398 | L5: 168.77347 | M5: 0.1529169 | N5: 164.85712 | O5: 0.15235103 | P5: 163.12205 | Q5: 0.15236755 | R5: 117.21195 | S5: 0.14357418 | T5: 110.81588 | U5: 0.1415542 | V5: 108.79939 | W5: 0.14045631 | X5: 103.87381 | Y5: 0.13949999
A6: Mar | B6: 133.75821 | C6: 0.11094469 | D6: 133.75821 | E6: 0.11094469 | F6: 133.75821 | G6: 0.11094469 | H6: 133.75821 | I6: 0.11094469 | J6: 178.03504 | K6: 0.11688059 | L6: 170.2298 | M6: 0.11528999 | N6: 157.74136 | O6: 0.1135528 | P6: 153.89711 | Q6: 0.11301811 | R6: 118.41763 | S6: 0.10547197 | T6: 103.56782 | U6: 0.10406252 | V6: 96.216176 | W6: 0.10356976 | X6: 94.564935 | Y6: 0.10306748
A7: Apr | B7: 114.72406 | C7: 0.094764425 | D7: 114.72406 | E7: 0.094764425 | F7: 114.72406 | G7: 0.094764425 | H7: 114.72406 | I7: 0.094764425 | J7: 153.99551 | K7: 0.10121807 | L7: 145.27395 | M7: 0.099115024 | N7: 134.67395 | O7: 0.098109145 | P7: 130.75789 | Q7: 0.097319124 | R7: 105.40796 | S7: 0.08976944 | T7: 88.573649 | U7: 0.086673335 | V7: 79.171088 | W7: 0.085457855 | X7: 75.504411 | Y7: 0.08477259
A8: May | B8: 108.7156 | C8: 0.094547987 | D8: 108.7156 | E8: 0.094547987 | F8: 108.7156 | G8: 0.094547987 | H8: 108.7156 | I8: 0.094547987 | J8: 132.95749 | K8: 0.096766267 | L8: 128.67747 | M8: 0.095974635 | N8: 122.42881 | O8: 0.095518444 | P8: 119.19586 | Q8: 0.095627735 | R8: 89.697032 | S8: 0.086993545 | T8: 76.734396 | U8: 0.08541012 | V8: 66.073509 | W8: 0.08351665 | X8: 52.201478 | Y8: 0.075954127
A9: Jun | B9: 115.96638 | C9: 0.092148778 | D9: 115.96638 | E9: 0.092148778 | F9: 115.96638 | G9: 0.092148778 | H9: 115.96638 | I9: 0.092148778 | J9: 134.31252 | K9: 0.096827769 | L9: 132.45389 | M9: 0.096270116 | N9: 127.35804 | O9: 0.094935735 | P9: 123.27803 | Q9: 0.093735573 | R9: 81.849885 | S9: 0.087217268 | T9: 69.340986 | U9: 0.08569922 | V9: 55.232625 | W9: 0.082784184 | X9: 50.037901 | Y9: 0.079520227
A10: Jul | B10: 113.55889 | C10: 0.10197308 | D10: 113.55889 | E10: 0.10197308 | F10: 113.55889 | G10: 0.10197308 | H10: 113.55889 | I10: 0.10197308 | J10: 132.86414 | K10: 0.10474779 | L10: 132.34034 | M10: 0.10462405 | N10: 126.99076 | O10: 0.10386494 | P10: 123.38002 | Q10: 0.10297332 | R10: 73.268821 | S10: 0.094169037 | T10: 59.542674 | U10: 0.0919669 | V10: 52.807308 | W10: 0.091295696 | X10: 51.192539 | Y10: 0.091454204
A11: Aug | B11: 111.56374 | C11: 0.083864344 | D11: 111.56374 | E11: 0.083864344 | F11: 111.56374 | G11: 0.083864344 | H11: 111.56374 | I11: 0.083864344 | J11: 138.2154 | K11: 0.086511336 | L11: 136.653 | M11: 0.086355521 | N11: 130.20747 | O11: 0.085792046 | P11: 126.47516 | Q11: 0.085220077 | R11: 77.426183 | S11: 0.076466926 | T11: 61.657417 | U11: 0.074040908 | V11: 48.121871 | W11: 0.0716997 | X11: 40.412629 | Y11: 0.070889925
A12: Sep | B12: 152.72742 | C12: 0.097608897 | D12: 152.72742 | E12: 0.097608897 | F12: 152.72742 | G12: 0.097608897 | H12: 152.72742 | I12: 0.097608897 | J12: 163.85416 | K12: 0.099835739 | L12: 162.85614 | M12: 0.099527258 | N12: 159.38364 | O12: 0.098992563 | P12: 157.02068 | Q12: 0.098622518 | R12: 102.34104 | S12: 0.083214345 | T12: 89.552408 | U12: 0.081434812 | V12: 83.761705 | W12: 0.080817436 | X12: 83.442876 | Y12: 0.080261217
A13: Oct | B13: 130.94103 | C13: 0.11195303 | D13: 130.94103 | E13: 0.11195303 | F13: 130.94103 | G13: 0.11195303 | H13: 130.94103 | I13: 0.11195303 | J13: 154.66746 | K13: 0.11825803 | L13: 145.82241 | M13: 0.11525943 | N13: 140.57093 | O13: 0.11396399 | P13: 138.86655 | Q13: 0.113942 | R13: 93.421961 | S13: 0.097181736 | T13: 80.986883 | U13: 0.09648124 | V13: 78.679086 | W13: 0.096649297 | X13: 79.00851 | Y13: 0.096224022
A14: Nov | B14: 98.317588 | C14: 0.10624492 | D14: 98.317588 | E14: 0.10624492 | F14: 98.317588 | G14: 0.10624492 | H14: 98.317588 | I14: 0.10624492 | J14: 144.44783 | K14: 0.11560506 | L14: 135.65523 | M14: 0.11183272 | N14: 129.18666 | O14: 0.10966403 | P14: 127.93616 | Q14: 0.10949064 | R14: 91.701993 | S14: 0.1008727 | T14: 81.414627 | U14: 0.099496109 | V14: 77.005584 | W14: 0.098184123 | X14: 75.869624 | Y14: 0.097918393
A15: Dec | B15: 119.67745 | C15: 0.10613895 | D15: 119.67745 | E15: 0.10613895 | F15: 119.67745 | G15: 0.10613895 | H15: 119.67745 | I15: 0.10613895 | J15: 181.46726 | K15: 0.11611018 | L15: 176.6597 | M15: 0.11472383 | N15: 172.73805 | O15: 0.11390563 | P15: 170.59243 | Q15: 0.11353706 | R15: 137.04447 | S15: 0.10635855 | T15: 128.6453 | U15: 0.10495131 | V15: 120.58069 | W15: 0.10355812 | X15: 110.92558 | Y15: 0.10222611

Sheet Monthly_Elasticity
A1: Monthly Elasticity ε — Month-on-Month Aggregate Method
A3: Month | B3: A-10kWh ε_m (-) | C3: A-15kWh ε_m (-) | D3: A-20kWh ε_m (-) | E3: A-30kWh ε_m (-) | F3: B-10kWh ε_m (-) | G3: B-15kWh ε_m (-) | H3: B-20kWh ε_m (-) | I3: B-30kWh ε_m (-) | J3: C-10kWh ε_m (-) | K3: C-15kWh ε_m (-) | L3: C-20kWh ε_m (-) | M3: C-30kWh ε_m (-)
A4: Jan
A5: Feb | B5: =IFERROR(((Monthly_Aggregates!B5-Monthly_Aggregates!B4)/Monthly_Aggregates!B4)/((Monthly_Aggregates!C5-Monthly_Aggregates!C4)/Monthly_Aggregates!C4),"") -> -0.096316943 | C5: =IFERROR(((Monthly_Aggregates!D5-Monthly_Aggregates!D4)/Monthly_Aggregates!D4)/((Monthly_Aggregates!E5-Monthly_Aggregates!E4)/Monthly_Aggregates!E4),"") -> -0.011864351 | D5: =IFERROR(((Monthly_Aggregates!F5-Monthly_Aggregates!F4)/Monthly_Aggregates!F4)/((Monthly_Aggregates!G5-Monthly_Aggregates!G4)/Monthly_Aggregates!G4),"") -> -0.011864351 | E5: =IFERROR(((Monthly_Aggregates!H5-Monthly_Aggregates!H4)/Monthly_Aggregates!H4)/((Monthly_Aggregates!I5-Monthly_Aggregates!I4)/Monthly_Aggregates!I4),"") -> -0.011864351 | F5: =IFERROR(((Monthly_Aggregates!J5-Monthly_Aggregates!J4)/Monthly_Aggregates!J4)/((Monthly_Aggregates!K5-Monthly_Aggregates!K4)/Monthly_Aggregates!K4),"") -> -0.8394471 | G5: =IFERROR(((Monthly_Aggregates!L5-Monthly_Aggregates!L4)/Monthly_Aggregates!L4)/((Monthly_Aggregates!M5-Monthly_Aggregates!M4)/Monthly_Aggregates!M4),"") -> -0.74426653 | H5: =IFERROR(((Monthly_Aggregates!N5-Monthly_Aggregates!N4)/Monthly_Aggregates!N4)/((Monthly_Aggregates!O5-Monthly_Aggregates!O4)/Monthly_Aggregates!O4),"") -> -0.69161921 | I5: =IFERROR(((Monthly_Aggregates!P5-Monthly_Aggregates!P4)/Monthly_Aggregates!P4)/((Monthly_Aggregates!Q5-Monthly_Aggregates!Q4)/Monthly_Aggregates!Q4),"") -> -0.65353708 | J5: =IFERROR(((Monthly_Aggregates!R5-Monthly_Aggregates!R4)/Monthly_Aggregates!R4)/((Monthly_Aggregates!S5-Monthly_Aggregates!S4)/Monthly_Aggregates!S4),"") -> -0.99169425 | K5: =IFERROR(((Monthly_Aggregates!T5-Monthly_Aggregates!T4)/Monthly_Aggregates!T4)/((Monthly_Aggregates!U5-Monthly_Aggregates!U4)/Monthly_Aggregates!U4),"") -> -1.13344 | L5: =IFERROR(((Monthly_Aggregates!V5-Monthly_Aggregates!V4)/Monthly_Aggregates!V4)/((Monthly_Aggregates!W5-Monthly_Aggregates!W4)/Monthly_Aggregates!W4),"") -> -1.1925348 | M5: =IFERROR(((Monthly_Aggregates!X5-Monthly_Aggregates!X4)/Monthly_Aggregates!X4)/((Monthly_Aggregates!Y5-Monthly_Aggregates!Y4)/Monthly_Aggregates!Y4),"") -> -1.3252386
A6: Mar | B6: =IFERROR(((Monthly_Aggregates!B6-Monthly_Aggregates!B5)/Monthly_Aggregates!B5)/((Monthly_Aggregates!C6-Monthly_Aggregates!C5)/Monthly_Aggregates!C5),"") -> 0.33215669 | C6: =IFERROR(((Monthly_Aggregates!D6-Monthly_Aggregates!D5)/Monthly_Aggregates!D5)/((Monthly_Aggregates!E6-Monthly_Aggregates!E5)/Monthly_Aggregates!E5),"") -> 0.33215669 | D6: =IFERROR(((Monthly_Aggregates!F6-Monthly_Aggregates!F5)/Monthly_Aggregates!F5)/((Monthly_Aggregates!G6-Monthly_Aggregates!G5)/Monthly_Aggregates!G5),"") -> 0.33215669 | E6: =IFERROR(((Monthly_Aggregates!H6-Monthly_Aggregates!H5)/Monthly_Aggregates!H5)/((Monthly_Aggregates!I6-Monthly_Aggregates!I5)/Monthly_Aggregates!I5),"") -> 0.33215669 | F6: =IFERROR(((Monthly_Aggregates!J6-Monthly_Aggregates!J5)/Monthly_Aggregates!J5)/((Monthly_Aggregates!K6-Monthly_Aggregates!K5)/Monthly_Aggregates!K5),"") -> -0.1450447 | G6: =IFERROR(((Monthly_Aggregates!L6-Monthly_Aggregates!L5)/Monthly_Aggregates!L5)/((Monthly_Aggregates!M6-Monthly_Aggregates!M5)/Monthly_Aggregates!M5),"") -> -0.03506819 | H6: =IFERROR(((Monthly_Aggregates!N6-Monthly_Aggregates!N5)/Monthly_Aggregates!N5)/((Monthly_Aggregates!O6-Monthly_Aggregates!O5)/Monthly_Aggregates!O5),"") -> 0.16949114 | I6: =IFERROR(((Monthly_Aggregates!P6-Monthly_Aggregates!P5)/Monthly_Aggregates!P5)/((Monthly_Aggregates!Q6-Monthly_Aggregates!Q5)/Monthly_Aggregates!Q5),"") -> 0.21898022 | J6: =IFERROR(((Monthly_Aggregates!R6-Monthly_Aggregates!R5)/Monthly_Aggregates!R5)/((Monthly_Aggregates!S6-Monthly_Aggregates!S5)/Monthly_Aggregates!S5),"") -> -0.038760128 | K6: =IFERROR(((Monthly_Aggregates!T6-Monthly_Aggregates!T5)/Monthly_Aggregates!T5)/((Monthly_Aggregates!U6-Monthly_Aggregates!U5)/Monthly_Aggregates!U5),"") -> 0.24694928 | L6: =IFERROR(((Monthly_Aggregates!V6-Monthly_Aggregates!V5)/Monthly_Aggregates!V5)/((Monthly_Aggregates!W6-Monthly_Aggregates!W5)/Monthly_Aggregates!W5),"") -> 0.44039092 | M6: =IFERROR(((Monthly_Aggregates!X6-Monthly_Aggregates!X5)/Monthly_Aggregates!X5)/((Monthly_Aggregates!Y6-Monthly_Aggregates!Y5)/Monthly_Aggregates!Y5),"") -> 0.343144
A7: Apr | B7: =IFERROR(((Monthly_Aggregates!B7-Monthly_Aggregates!B6)/Monthly_Aggregates!B6)/((Monthly_Aggregates!C7-Monthly_Aggregates!C6)/Monthly_Aggregates!C6),"") -> 0.97573945 | C7: =IFERROR(((Monthly_Aggregates!D7-Monthly_Aggregates!D6)/Monthly_Aggregates!D6)/((Monthly_Aggregates!E7-Monthly_Aggregates!E6)/Monthly_Aggregates!E6),"") -> 0.97573945 | D7: =IFERROR(((Monthly_Aggregates!F7-Monthly_Aggregates!F6)/Monthly_Aggregates!F6)/((Monthly_Aggregates!G7-Monthly_Aggregates!G6)/Monthly_Aggregates!G6),"") -> 0.97573945 | E7: =IFERROR(((Monthly_Aggregates!H7-Monthly_Aggregates!H6)/Monthly_Aggregates!H6)/((Monthly_Aggregates!I7-Monthly_Aggregates!I6)/Monthly_Aggregates!I6),"") -> 0.97573945 | F7: =IFERROR(((Monthly_Aggregates!J7-Monthly_Aggregates!J6)/Monthly_Aggregates!J6)/((Monthly_Aggregates!K7-Monthly_Aggregates!K6)/Monthly_Aggregates!K6),"") -> 1.0076302 | G7: =IFERROR(((Monthly_Aggregates!L7-Monthly_Aggregates!L6)/Monthly_Aggregates!L6)/((Monthly_Aggregates!M7-Monthly_Aggregates!M6)/Monthly_Aggregates!M6),"") -> 1.0449247 | H7: =IFERROR(((Monthly_Aggregates!N7-Monthly_Aggregates!N6)/Monthly_Aggregates!N6)/((Monthly_Aggregates!O7-Monthly_Aggregates!O6)/Monthly_Aggregates!O6),"") -> 1.0752286 | I7: =IFERROR(((Monthly_Aggregates!P7-Monthly_Aggregates!P6)/Monthly_Aggregates!P6)/((Monthly_Aggregates!Q7-Monthly_Aggregates!Q6)/Monthly_Aggregates!Q6),"") -> 1.0824175 | J7: =IFERROR(((Monthly_Aggregates!R7-Monthly_Aggregates!R6)/Monthly_Aggregates!R6)/((Monthly_Aggregates!S7-Monthly_Aggregates!S6)/Monthly_Aggregates!S6),"") -> 0.73793377 | K7: =IFERROR(((Monthly_Aggregates!T7-Monthly_Aggregates!T6)/Monthly_Aggregates!T6)/((Monthly_Aggregates!U7-Monthly_Aggregates!U6)/Monthly_Aggregates!U6),"") -> 0.86638877 | L7: =IFERROR(((Monthly_Aggregates!V7-Monthly_Aggregates!V6)/Monthly_Aggregates!V6)/((Monthly_Aggregates!W7-Monthly_Aggregates!W6)/Monthly_Aggregates!W6),"") -> 1.0130246 | M7: =IFERROR(((Monthly_Aggregates!X7-Monthly_Aggregates!X6)/Monthly_Aggregates!X6)/((Monthly_Aggregates!Y7-Monthly_Aggregates!Y6)/Monthly_Aggregates!Y6),"") -> 1.1355246
A8: May | B8: =IFERROR(((Monthly_Aggregates!B8-Monthly_Aggregates!B7)/Monthly_Aggregates!B7)/((Monthly_Aggregates!C8-Monthly_Aggregates!C7)/Monthly_Aggregates!C7),"") -> 22.930942 | C8: =IFERROR(((Monthly_Aggregates!D8-Monthly_Aggregates!D7)/Monthly_Aggregates!D7)/((Monthly_Aggregates!E8-Monthly_Aggregates!E7)/Monthly_Aggregates!E7),"") -> 22.930942 | D8: =IFERROR(((Monthly_Aggregates!F8-Monthly_Aggregates!F7)/Monthly_Aggregates!F7)/((Monthly_Aggregates!G8-Monthly_Aggregates!G7)/Monthly_Aggregates!G7),"") -> 22.930942 | E8: =IFERROR(((Monthly_Aggregates!H8-Monthly_Aggregates!H7)/Monthly_Aggregates!H7)/((Monthly_Aggregates!I8-Monthly_Aggregates!I7)/Monthly_Aggregates!I7),"") -> 22.930942 | F8: =IFERROR(((Monthly_Aggregates!J8-Monthly_Aggregates!J7)/Monthly_Aggregates!J7)/((Monthly_Aggregates!K8-Monthly_Aggregates!K7)/Monthly_Aggregates!K7),"") -> 3.1061244 | G8: =IFERROR(((Monthly_Aggregates!L8-Monthly_Aggregates!L7)/Monthly_Aggregates!L7)/((Monthly_Aggregates!M8-Monthly_Aggregates!M7)/Monthly_Aggregates!M7),"") -> 3.605657 | H8: =IFERROR(((Monthly_Aggregates!N8-Monthly_Aggregates!N7)/Monthly_Aggregates!N7)/((Monthly_Aggregates!O8-Monthly_Aggregates!O7)/Monthly_Aggregates!O7),"") -> 3.4432806 | I8: =IFERROR(((Monthly_Aggregates!P8-Monthly_Aggregates!P7)/Monthly_Aggregates!P7)/((Monthly_Aggregates!Q8-Monthly_Aggregates!Q7)/Monthly_Aggregates!Q7),"") -> 5.0876931 | J8: =IFERROR(((Monthly_Aggregates!R8-Monthly_Aggregates!R7)/Monthly_Aggregates!R7)/((Monthly_Aggregates!S8-Monthly_Aggregates!S7)/Monthly_Aggregates!S7),"") -> 4.8200763 | K8: =IFERROR(((Monthly_Aggregates!T8-Monthly_Aggregates!T7)/Monthly_Aggregates!T7)/((Monthly_Aggregates!U8-Monthly_Aggregates!U7)/Monthly_Aggregates!U7),"") -> 9.1712358 | L8: =IFERROR(((Monthly_Aggregates!V8-Monthly_Aggregates!V7)/Monthly_Aggregates!V7)/((Monthly_Aggregates!W8-Monthly_Aggregates!W7)/Monthly_Aggregates!W7),"") -> 7.2829116 | M8: =IFERROR(((Monthly_Aggregates!X8-Monthly_Aggregates!X7)/Monthly_Aggregates!X7)/((Monthly_Aggregates!Y8-Monthly_Aggregates!Y7)/Monthly_Aggregates!Y7),"") -> 2.9668858
A9: Jun | B9: =IFERROR(((Monthly_Aggregates!B9-Monthly_Aggregates!B8)/Monthly_Aggregates!B8)/((Monthly_Aggregates!C9-Monthly_Aggregates!C8)/Monthly_Aggregates!C8),"") -> -2.6283105 | C9: =IFERROR(((Monthly_Aggregates!D9-Monthly_Aggregates!D8)/Monthly_Aggregates!D8)/((Monthly_Aggregates!E9-Monthly_Aggregates!E8)/Monthly_Aggregates!E8),"") -> -2.6283105 | D9: =IFERROR(((Monthly_Aggregates!F9-Monthly_Aggregates!F8)/Monthly_Aggregates!F8)/((Monthly_Aggregates!G9-Monthly_Aggregates!G8)/Monthly_Aggregates!G8),"") -> -2.6283105 | E9: =IFERROR(((Monthly_Aggregates!H9-Monthly_Aggregates!H8)/Monthly_Aggregates!H8)/((Monthly_Aggregates!I9-Monthly_Aggregates!I8)/Monthly_Aggregates!I8),"") -> -2.6283105 | F9: =IFERROR(((Monthly_Aggregates!J9-Monthly_Aggregates!J8)/Monthly_Aggregates!J8)/((Monthly_Aggregates!K9-Monthly_Aggregates!K8)/Monthly_Aggregates!K8),"") -> 16.035319 | G9: =IFERROR(((Monthly_Aggregates!L9-Monthly_Aggregates!L8)/Monthly_Aggregates!L8)/((Monthly_Aggregates!M9-Monthly_Aggregates!M8)/Monthly_Aggregates!M8),"") -> 9.532438 | H9: =IFERROR(((Monthly_Aggregates!N9-Monthly_Aggregates!N8)/Monthly_Aggregates!N8)/((Monthly_Aggregates!O9-Monthly_Aggregates!O8)/Monthly_Aggregates!O8),"") -> -6.5997944 | I9: =IFERROR(((Monthly_Aggregates!P9-Monthly_Aggregates!P8)/Monthly_Aggregates!P8)/((Monthly_Aggregates!Q9-Monthly_Aggregates!Q8)/Monthly_Aggregates!Q8),"") -> -1.7308371 | J9: =IFERROR(((Monthly_Aggregates!R9-Monthly_Aggregates!R8)/Monthly_Aggregates!R8)/((Monthly_Aggregates!S9-Monthly_Aggregates!S8)/Monthly_Aggregates!S8),"") -> -34.018185 | K9: =IFERROR(((Monthly_Aggregates!T9-Monthly_Aggregates!T8)/Monthly_Aggregates!T8)/((Monthly_Aggregates!U9-Monthly_Aggregates!U8)/Monthly_Aggregates!U8),"") -> -28.465278 | L9: =IFERROR(((Monthly_Aggregates!V9-Monthly_Aggregates!V8)/Monthly_Aggregates!V8)/((Monthly_Aggregates!W9-Monthly_Aggregates!W8)/Monthly_Aggregates!W8),"") -> 18.707815 | M9: =IFERROR(((Monthly_Aggregates!X9-Monthly_Aggregates!X8)/Monthly_Aggregates!X8)/((Monthly_Aggregates!Y9-Monthly_Aggregates!Y8)/Monthly_Aggregates!Y8),"") -> -0.88276979
A10: Jul | B10: =IFERROR(((Monthly_Aggregates!B10-Monthly_Aggregates!B9)/Monthly_Aggregates!B9)/((Monthly_Aggregates!C10-Monthly_Aggregates!C9)/Monthly_Aggregates!C9),"") -> -0.19472408 | C10: =IFERROR(((Monthly_Aggregates!D10-Monthly_Aggregates!D9)/Monthly_Aggregates!D9)/((Monthly_Aggregates!E10-Monthly_Aggregates!E9)/Monthly_Aggregates!E9),"") -> -0.19472408 | D10: =IFERROR(((Monthly_Aggregates!F10-Monthly_Aggregates!F9)/Monthly_Aggregates!F9)/((Monthly_Aggregates!G10-Monthly_Aggregates!G9)/Monthly_Aggregates!G9),"") -> -0.19472408 | E10: =IFERROR(((Monthly_Aggregates!H10-Monthly_Aggregates!H9)/Monthly_Aggregates!H9)/((Monthly_Aggregates!I10-Monthly_Aggregates!I9)/Monthly_Aggregates!I9),"") -> -0.19472408 | F10: =IFERROR(((Monthly_Aggregates!J10-Monthly_Aggregates!J9)/Monthly_Aggregates!J9)/((Monthly_Aggregates!K10-Monthly_Aggregates!K9)/Monthly_Aggregates!K9),"") -> -0.13183803 | G10: =IFERROR(((Monthly_Aggregates!L10-Monthly_Aggregates!L9)/Monthly_Aggregates!L9)/((Monthly_Aggregates!M10-Monthly_Aggregates!M9)/Monthly_Aggregates!M9),"") -> -0.0098791044 | H10: =IFERROR(((Monthly_Aggregates!N10-Monthly_Aggregates!N9)/Monthly_Aggregates!N9)/((Monthly_Aggregates!O10-Monthly_Aggregates!O9)/Monthly_Aggregates!O9),"") -> -0.030661478 | I10: =IFERROR(((Monthly_Aggregates!P10-Monthly_Aggregates!P9)/Monthly_Aggregates!P9)/((Monthly_Aggregates!Q10-Monthly_Aggregates!Q9)/Monthly_Aggregates!Q9),"") -> 0.008394646 | J10: =IFERROR(((Monthly_Aggregates!R10-Monthly_Aggregates!R9)/Monthly_Aggregates!R9)/((Monthly_Aggregates!S10-Monthly_Aggregates!S9)/Monthly_Aggregates!S9),"") -> -1.3153163 | K10: =IFERROR(((Monthly_Aggregates!T10-Monthly_Aggregates!T9)/Monthly_Aggregates!T9)/((Monthly_Aggregates!U10-Monthly_Aggregates!U9)/Monthly_Aggregates!U9),"") -> -1.9321077 | L10: =IFERROR(((Monthly_Aggregates!V10-Monthly_Aggregates!V9)/Monthly_Aggregates!V9)/((Monthly_Aggregates!W10-Monthly_Aggregates!W9)/Monthly_Aggregates!W9),"") -> -0.42708408 | M10: =IFERROR(((Monthly_Aggregates!X10-Monthly_Aggregates!X9)/Monthly_Aggregates!X9)/((Monthly_Aggregates!Y10-Monthly_Aggregates!Y9)/Monthly_Aggregates!Y9),"") -> 0.15375855
A11: Aug | B11: =IFERROR(((Monthly_Aggregates!B11-Monthly_Aggregates!B10)/Monthly_Aggregates!B10)/((Monthly_Aggregates!C11-Monthly_Aggregates!C10)/Monthly_Aggregates!C10),"") -> 0.098935343 | C11: =IFERROR(((Monthly_Aggregates!D11-Monthly_Aggregates!D10)/Monthly_Aggregates!D10)/((Monthly_Aggregates!E11-Monthly_Aggregates!E10)/Monthly_Aggregates!E10),"") -> 0.098935343 | D11: =IFERROR(((Monthly_Aggregates!F11-Monthly_Aggregates!F10)/Monthly_Aggregates!F10)/((Monthly_Aggregates!G11-Monthly_Aggregates!G10)/Monthly_Aggregates!G10),"") -> 0.098935343 | E11: =IFERROR(((Monthly_Aggregates!H11-Monthly_Aggregates!H10)/Monthly_Aggregates!H10)/((Monthly_Aggregates!I11-Monthly_Aggregates!I10)/Monthly_Aggregates!I10),"") -> 0.098935343 | F11: =IFERROR(((Monthly_Aggregates!J11-Monthly_Aggregates!J10)/Monthly_Aggregates!J10)/((Monthly_Aggregates!K11-Monthly_Aggregates!K10)/Monthly_Aggregates!K10),"") -> -0.23134117 | G11: =IFERROR(((Monthly_Aggregates!L11-Monthly_Aggregates!L10)/Monthly_Aggregates!L10)/((Monthly_Aggregates!M11-Monthly_Aggregates!M10)/Monthly_Aggregates!M10),"") -> -0.18662991 | H11: =IFERROR(((Monthly_Aggregates!N11-Monthly_Aggregates!N10)/Monthly_Aggregates!N10)/((Monthly_Aggregates!O11-Monthly_Aggregates!O10)/Monthly_Aggregates!O10),"") -> -0.14557328 | I11: =IFERROR(((Monthly_Aggregates!P11-Monthly_Aggregates!P10)/Monthly_Aggregates!P10)/((Monthly_Aggregates!Q11-Monthly_Aggregates!Q10)/Monthly_Aggregates!Q10),"") -> -0.14550629 | J11: =IFERROR(((Monthly_Aggregates!R11-Monthly_Aggregates!R10)/Monthly_Aggregates!R10)/((Monthly_Aggregates!S11-Monthly_Aggregates!S10)/Monthly_Aggregates!S10),"") -> -0.3018434 | K11: =IFERROR(((Monthly_Aggregates!T11-Monthly_Aggregates!T10)/Monthly_Aggregates!T10)/((Monthly_Aggregates!U11-Monthly_Aggregates!U10)/Monthly_Aggregates!U10),"") -> -0.1822122 | L11: =IFERROR(((Monthly_Aggregates!V11-Monthly_Aggregates!V10)/Monthly_Aggregates!V10)/((Monthly_Aggregates!W11-Monthly_Aggregates!W10)/Monthly_Aggregates!W10),"") -> 0.41337012 | M11: =IFERROR(((Monthly_Aggregates!X11-Monthly_Aggregates!X10)/Monthly_Aggregates!X10)/((Monthly_Aggregates!Y11-Monthly_Aggregates!Y10)/Monthly_Aggregates!Y10),"") -> 0.93648032
A12: Sep | B12: =IFERROR(((Monthly_Aggregates!B12-Monthly_Aggregates!B11)/Monthly_Aggregates!B11)/((Monthly_Aggregates!C12-Monthly_Aggregates!C11)/Monthly_Aggregates!C11),"") -> 2.2513233 | C12: =IFERROR(((Monthly_Aggregates!D12-Monthly_Aggregates!D11)/Monthly_Aggregates!D11)/((Monthly_Aggregates!E12-Monthly_Aggregates!E11)/Monthly_Aggregates!E11),"") -> 2.2513233 | D12: =IFERROR(((Monthly_Aggregates!F12-Monthly_Aggregates!F11)/Monthly_Aggregates!F11)/((Monthly_Aggregates!G12-Monthly_Aggregates!G11)/Monthly_Aggregates!G11),"") -> 2.2513233 | E12: =IFERROR(((Monthly_Aggregates!H12-Monthly_Aggregates!H11)/Monthly_Aggregates!H11)/((Monthly_Aggregates!I12-Monthly_Aggregates!I11)/Monthly_Aggregates!I11),"") -> 2.2513233 | F12: =IFERROR(((Monthly_Aggregates!J12-Monthly_Aggregates!J11)/Monthly_Aggregates!J11)/((Monthly_Aggregates!K12-Monthly_Aggregates!K11)/Monthly_Aggregates!K11),"") -> 1.2043864 | G12: =IFERROR(((Monthly_Aggregates!L12-Monthly_Aggregates!L11)/Monthly_Aggregates!L11)/((Monthly_Aggregates!M12-Monthly_Aggregates!M11)/Monthly_Aggregates!M11),"") -> 1.2571328 | H12: =IFERROR(((Monthly_Aggregates!N12-Monthly_Aggregates!N11)/Monthly_Aggregates!N11)/((Monthly_Aggregates!O12-Monthly_Aggregates!O11)/Monthly_Aggregates!O11),"") -> 1.4562916 | I12: =IFERROR(((Monthly_Aggregates!P12-Monthly_Aggregates!P11)/Monthly_Aggregates!P11)/((Monthly_Aggregates!Q12-Monthly_Aggregates!Q11)/Monthly_Aggregates!Q11),"") -> 1.5356786 | J12: =IFERROR(((Monthly_Aggregates!R12-Monthly_Aggregates!R11)/Monthly_Aggregates!R11)/((Monthly_Aggregates!S12-Monthly_Aggregates!S11)/Monthly_Aggregates!S11),"") -> 3.6467536 | K12: =IFERROR(((Monthly_Aggregates!T12-Monthly_Aggregates!T11)/Monthly_Aggregates!T11)/((Monthly_Aggregates!U12-Monthly_Aggregates!U11)/Monthly_Aggregates!U11),"") -> 4.5304239 | L12: =IFERROR(((Monthly_Aggregates!V12-Monthly_Aggregates!V11)/Monthly_Aggregates!V11)/((Monthly_Aggregates!W12-Monthly_Aggregates!W11)/Monthly_Aggregates!W11),"") -> 5.8240285 | M12: =IFERROR(((Monthly_Aggregates!X12-Monthly_Aggregates!X11)/Monthly_Aggregates!X11)/((Monthly_Aggregates!Y12-Monthly_Aggregates!Y11)/Monthly_Aggregates!Y11),"") -> 8.0545592
A13: Oct | B13: =IFERROR(((Monthly_Aggregates!B13-Monthly_Aggregates!B12)/Monthly_Aggregates!B12)/((Monthly_Aggregates!C13-Monthly_Aggregates!C12)/Monthly_Aggregates!C12),"") -> -0.97069625 | C13: =IFERROR(((Monthly_Aggregates!D13-Monthly_Aggregates!D12)/Monthly_Aggregates!D12)/((Monthly_Aggregates!E13-Monthly_Aggregates!E12)/Monthly_Aggregates!E12),"") -> -0.97069625 | D13: =IFERROR(((Monthly_Aggregates!F13-Monthly_Aggregates!F12)/Monthly_Aggregates!F12)/((Monthly_Aggregates!G13-Monthly_Aggregates!G12)/Monthly_Aggregates!G12),"") -> -0.97069625 | E13: =IFERROR(((Monthly_Aggregates!H13-Monthly_Aggregates!H12)/Monthly_Aggregates!H12)/((Monthly_Aggregates!I13-Monthly_Aggregates!I12)/Monthly_Aggregates!I12),"") -> -0.97069625 | F13: =IFERROR(((Monthly_Aggregates!J13-Monthly_Aggregates!J12)/Monthly_Aggregates!J12)/((Monthly_Aggregates!K13-Monthly_Aggregates!K12)/Monthly_Aggregates!K12),"") -> -0.30383968 | G13: =IFERROR(((Monthly_Aggregates!L13-Monthly_Aggregates!L12)/Monthly_Aggregates!L12)/((Monthly_Aggregates!M13-Monthly_Aggregates!M12)/Monthly_Aggregates!M12),"") -> -0.66169661 | H13: =IFERROR(((Monthly_Aggregates!N13-Monthly_Aggregates!N12)/Monthly_Aggregates!N12)/((Monthly_Aggregates!O13-Monthly_Aggregates!O12)/Monthly_Aggregates!O12),"") -> -0.78045328 | I13: =IFERROR(((Monthly_Aggregates!P13-Monthly_Aggregates!P12)/Monthly_Aggregates!P12)/((Monthly_Aggregates!Q13-Monthly_Aggregates!Q12)/Monthly_Aggregates!Q12),"") -> -0.74430469 | J13: =IFERROR(((Monthly_Aggregates!R13-Monthly_Aggregates!R12)/Monthly_Aggregates!R12)/((Monthly_Aggregates!S13-Monthly_Aggregates!S12)/Monthly_Aggregates!S12),"") -> -0.51922184 | K13: =IFERROR(((Monthly_Aggregates!T13-Monthly_Aggregates!T12)/Monthly_Aggregates!T12)/((Monthly_Aggregates!U13-Monthly_Aggregates!U12)/Monthly_Aggregates!U12),"") -> -0.51767046 | L13: =IFERROR(((Monthly_Aggregates!V13-Monthly_Aggregates!V12)/Monthly_Aggregates!V12)/((Monthly_Aggregates!W13-Monthly_Aggregates!W12)/Monthly_Aggregates!W12),"") -> -0.30975272 | M13: =IFERROR(((Monthly_Aggregates!X13-Monthly_Aggregates!X12)/Monthly_Aggregates!X12)/((Monthly_Aggregates!Y13-Monthly_Aggregates!Y12)/Monthly_Aggregates!Y12),"") -> -0.2672014
A14: Nov | B14: =IFERROR(((Monthly_Aggregates!B14-Monthly_Aggregates!B13)/Monthly_Aggregates!B13)/((Monthly_Aggregates!C14-Monthly_Aggregates!C13)/Monthly_Aggregates!C13),"") -> 4.8864941 | C14: =IFERROR(((Monthly_Aggregates!D14-Monthly_Aggregates!D13)/Monthly_Aggregates!D13)/((Monthly_Aggregates!E14-Monthly_Aggregates!E13)/Monthly_Aggregates!E13),"") -> 4.8864941 | D14: =IFERROR(((Monthly_Aggregates!F14-Monthly_Aggregates!F13)/Monthly_Aggregates!F13)/((Monthly_Aggregates!G14-Monthly_Aggregates!G13)/Monthly_Aggregates!G13),"") -> 4.8864941 | E14: =IFERROR(((Monthly_Aggregates!H14-Monthly_Aggregates!H13)/Monthly_Aggregates!H13)/((Monthly_Aggregates!I14-Monthly_Aggregates!I13)/Monthly_Aggregates!I13),"") -> 4.8864941 | F14: =IFERROR(((Monthly_Aggregates!J14-Monthly_Aggregates!J13)/Monthly_Aggregates!J13)/((Monthly_Aggregates!K14-Monthly_Aggregates!K13)/Monthly_Aggregates!K13),"") -> 2.9453362 | G14: =IFERROR(((Monthly_Aggregates!L14-Monthly_Aggregates!L13)/Monthly_Aggregates!L13)/((Monthly_Aggregates!M14-Monthly_Aggregates!M13)/Monthly_Aggregates!M13),"") -> 2.3451763 | H14: =IFERROR(((Monthly_Aggregates!N14-Monthly_Aggregates!N13)/Monthly_Aggregates!N13)/((Monthly_Aggregates!O14-Monthly_Aggregates!O13)/Monthly_Aggregates!O13),"") -> 2.1464105 | I14: =IFERROR(((Monthly_Aggregates!P14-Monthly_Aggregates!P13)/Monthly_Aggregates!P13)/((Monthly_Aggregates!Q14-Monthly_Aggregates!Q13)/Monthly_Aggregates!Q13),"") -> 2.0147883 | J14: =IFERROR(((Monthly_Aggregates!R14-Monthly_Aggregates!R13)/Monthly_Aggregates!R13)/((Monthly_Aggregates!S14-Monthly_Aggregates!S13)/Monthly_Aggregates!S13),"") -> -0.48474833 | K14: =IFERROR(((Monthly_Aggregates!T14-Monthly_Aggregates!T13)/Monthly_Aggregates!T13)/((Monthly_Aggregates!U14-Monthly_Aggregates!U13)/Monthly_Aggregates!U13),"") -> 0.16902231 | L14: =IFERROR(((Monthly_Aggregates!V14-Monthly_Aggregates!V13)/Monthly_Aggregates!V13)/((Monthly_Aggregates!W14-Monthly_Aggregates!W13)/Monthly_Aggregates!W13),"") -> -1.339388 | M14: =IFERROR(((Monthly_Aggregates!X14-Monthly_Aggregates!X13)/Monthly_Aggregates!X13)/((Monthly_Aggregates!Y14-Monthly_Aggregates!Y13)/Monthly_Aggregates!Y13),"") -> -2.2561959
A15: Dec | B15: =IFERROR(((Monthly_Aggregates!B15-Monthly_Aggregates!B14)/Monthly_Aggregates!B14)/((Monthly_Aggregates!C15-Monthly_Aggregates!C14)/Monthly_Aggregates!C14),"") -> -217.81533 | C15: =IFERROR(((Monthly_Aggregates!D15-Monthly_Aggregates!D14)/Monthly_Aggregates!D14)/((Monthly_Aggregates!E15-Monthly_Aggregates!E14)/Monthly_Aggregates!E14),"") -> -217.81533 | D15: =IFERROR(((Monthly_Aggregates!F15-Monthly_Aggregates!F14)/Monthly_Aggregates!F14)/((Monthly_Aggregates!G15-Monthly_Aggregates!G14)/Monthly_Aggregates!G14),"") -> -217.81533 | E15: =IFERROR(((Monthly_Aggregates!H15-Monthly_Aggregates!H14)/Monthly_Aggregates!H14)/((Monthly_Aggregates!I15-Monthly_Aggregates!I14)/Monthly_Aggregates!I14),"") -> -217.81533 | F15: =IFERROR(((Monthly_Aggregates!J15-Monthly_Aggregates!J14)/Monthly_Aggregates!J14)/((Monthly_Aggregates!K15-Monthly_Aggregates!K14)/Monthly_Aggregates!K14),"") -> 58.654884 | G15: =IFERROR(((Monthly_Aggregates!L15-Monthly_Aggregates!L14)/Monthly_Aggregates!L14)/((Monthly_Aggregates!M15-Monthly_Aggregates!M14)/Monthly_Aggregates!M14),"") -> 11.692287 | H15: =IFERROR(((Monthly_Aggregates!N15-Monthly_Aggregates!N14)/Monthly_Aggregates!N14)/((Monthly_Aggregates!O15-Monthly_Aggregates!O14)/Monthly_Aggregates!O14),"") -> 8.7160357 | I15: =IFERROR(((Monthly_Aggregates!P15-Monthly_Aggregates!P14)/Monthly_Aggregates!P14)/((Monthly_Aggregates!Q15-Monthly_Aggregates!Q14)/Monthly_Aggregates!Q14),"") -> 9.0218446 | J15: =IFERROR(((Monthly_Aggregates!R15-Monthly_Aggregates!R14)/Monthly_Aggregates!R14)/((Monthly_Aggregates!S15-Monthly_Aggregates!S14)/Monthly_Aggregates!S14),"") -> 9.091928 | K15: =IFERROR(((Monthly_Aggregates!T15-Monthly_Aggregates!T14)/Monthly_Aggregates!T14)/((Monthly_Aggregates!U15-Monthly_Aggregates!U14)/Monthly_Aggregates!U14),"") -> 10.580759 | L15: =IFERROR(((Monthly_Aggregates!V15-Monthly_Aggregates!V14)/Monthly_Aggregates!V14)/((Monthly_Aggregates!W15-Monthly_Aggregates!W14)/Monthly_Aggregates!W14),"") -> 10.338556 | M15: =IFERROR(((Monthly_Aggregates!X15-Monthly_Aggregates!X14)/Monthly_Aggregates!X14)/((Monthly_Aggregates!Y15-Monthly_Aggregates!Y14)/Monthly_Aggregates!Y14),"") -> 10.50293

Sheet Annual_Aggregates
A1: Annual Aggregate Inputs
A3: Strategy | B3: Battery capacity (kWh) | C3: Scenario | D3: Annual E_grid (kWh) | E3: Annual weighted P (€/kWh) | F3: Reference
A4: A | B4: 10 | C4: A-10kWh | D4: 1496.5472 | E4: 0.10796339 | F4: Reference
A5: A | B5: 15 | C5: A-15kWh | D5: 1494.0439 | E5: 0.10788721 | F5: A-10kWh
A6: A | B6: 20 | C6: A-20kWh | D6: 1494.0439 | E6: 0.10788721 | F6: A-10kWh
A7: A | B7: 30 | C7: A-30kWh | D7: 1494.0439 | E7: 0.10788721 | F7: A-10kWh
A8: B | B8: 10 | C8: B-10kWh | D8: 1883.7244 | E8: 0.11322604 | F8: A-10kWh
A9: B | B9: 15 | C9: B-15kWh | D9: 1827.2941 | E9: 0.11179916 | F9: A-10kWh
A10: B | B10: 20 | C10: B-20kWh | D10: 1752.2664 | E10: 0.11092091 | F10: A-10kWh
A11: B | B11: 30 | C11: B-30kWh | D11: 1717.5997 | E11: 0.11062093 | F11: A-10kWh
A12: C | B12: 10 | C12: C-10kWh | D12: 1227.1164 | E12: 0.10203414 | F12: A-10kWh
A13: C | B13: 15 | C13: C-15kWh | D13: 1084.5539 | E13: 0.10126794 | F13: A-10kWh
A14: C | B14: 20 | C14: C-20kWh | D14: 997.85948 | E14: 0.10114259 | F14: A-10kWh
A15: C | B15: 30 | C15: C-30kWh | D15: 944.81302 | E15: 0.10035487 | F15: A-10kWh

Sheet Annual_Elasticity
A1: Annual Elasticity ε — Comparative and Weighted Measures
A3: Strategy | B3: Battery capacity (kWh) | C3: Scenario | D3: Annual aggregate ε vs A-10 (-) | E3: Annual weighted monthly ε (-) | F3: Annual E_grid (kWh) | G3: Annual weighted P (€/kWh)
A4: A | B4: 10 | C4: A-10kWh | E4: =IFERROR(SUMPRODUCT(Monthly_Aggregates!B5:B15,Monthly_Elasticity!B5:B15)/SUM(Monthly_Aggregates!B5:B15),"") -> -17.115213 | F4: =Annual_Aggregates!D4 -> 1496.5472 | G4: =Annual_Aggregates!E4 -> 0.10796339
A5: A | B5: 15 | C5: A-15kWh | D5: =IFERROR(((Annual_Aggregates!D5-Annual_Aggregates!$D$4)/Annual_Aggregates!$D$4)/((Annual_Aggregates!E5-Annual_Aggregates!$E$4)/Annual_Aggregates!$E$4),"") -> 2.3704509 | E5: =IFERROR(SUMPRODUCT(Monthly_Aggregates!D5:D15,Monthly_Elasticity!C5:C15)/SUM(Monthly_Aggregates!D5:D15),"") -> -17.106004 | F5: =Annual_Aggregates!D5 -> 1494.0439 | G5: =Annual_Aggregates!E5 -> 0.10788721
A6: A | B6: 20 | C6: A-20kWh | D6: =IFERROR(((Annual_Aggregates!D6-Annual_Aggregates!$D$4)/Annual_Aggregates!$D$4)/((Annual_Aggregates!E6-Annual_Aggregates!$E$4)/Annual_Aggregates!$E$4),"") -> 2.3704509 | E6: =IFERROR(SUMPRODUCT(Monthly_Aggregates!F5:F15,Monthly_Elasticity!D5:D15)/SUM(Monthly_Aggregates!F5:F15),"") -> -17.106004 | F6: =Annual_Aggregates!D6 -> 1494.0439 | G6: =Annual_Aggregates!E6 -> 0.10788721
A7: A | B7: 30 | C7: A-30kWh | D7: =IFERROR(((Annual_Aggregates!D7-Annual_Aggregates!$D$4)/Annual_Aggregates!$D$4)/((Annual_Aggregates!E7-Annual_Aggregates!$E$4)/Annual_Aggregates!$E$4),"") -> 2.3704509 | E7: =IFERROR(SUMPRODUCT(Monthly_Aggregates!H5:H15,Monthly_Elasticity!E5:E15)/SUM(Monthly_Aggregates!H5:H15),"") -> -17.106004 | F7: =Annual_Aggregates!D7 -> 1494.0439 | G7: =Annual_Aggregates!E7 -> 0.10788721
A8: B | B8: 10 | C8: B-10kWh | D8: =IFERROR(((Annual_Aggregates!D8-Annual_Aggregates!$D$4)/Annual_Aggregates!$D$4)/((Annual_Aggregates!E8-Annual_Aggregates!$E$4)/Annual_Aggregates!$E$4),"") -> 5.307518 | E8: =IFERROR(SUMPRODUCT(Monthly_Aggregates!J5:J15,Monthly_Elasticity!F5:F15)/SUM(Monthly_Aggregates!J5:J15),"") -> 8.1344545 | F8: =Annual_Aggregates!D8 -> 1883.7244 | G8: =Annual_Aggregates!E8 -> 0.11322604
A9: B | B9: 15 | C9: B-15kWh | D9: =IFERROR(((Annual_Aggregates!D9-Annual_Aggregates!$D$4)/Annual_Aggregates!$D$4)/((Annual_Aggregates!E9-Annual_Aggregates!$E$4)/Annual_Aggregates!$E$4),"") -> 6.2205644 | E9: =IFERROR(SUMPRODUCT(Monthly_Aggregates!L5:L15,Monthly_Elasticity!G5:G15)/SUM(Monthly_Aggregates!L5:L15),"") -> 2.5754723 | F9: =Annual_Aggregates!D9 -> 1827.2941 | G9: =Annual_Aggregates!E9 -> 0.11179916
A10: B | B10: 20 | C10: B-20kWh | D10: =IFERROR(((Annual_Aggregates!D10-Annual_Aggregates!$D$4)/Annual_Aggregates!$D$4)/((Annual_Aggregates!E10-Annual_Aggregates!$E$4)/Annual_Aggregates!$E$4),"") -> 6.2376655 | E10: =IFERROR(SUMPRODUCT(Monthly_Aggregates!N5:N15,Monthly_Elasticity!H5:H15)/SUM(Monthly_Aggregates!N5:N15),"") -> 0.97116214 | F10: =Annual_Aggregates!D10 -> 1752.2664 | G10: =Annual_Aggregates!E10 -> 0.11092091
A11: B | B11: 30 | C11: B-30kWh | D11: =IFERROR(((Annual_Aggregates!D11-Annual_Aggregates!$D$4)/Annual_Aggregates!$D$4)/((Annual_Aggregates!E11-Annual_Aggregates!$E$4)/Annual_Aggregates!$E$4),"") -> 6.0007051 | E11: =IFERROR(SUMPRODUCT(Monthly_Aggregates!P5:P15,Monthly_Elasticity!I5:I15)/SUM(Monthly_Aggregates!P5:P15),"") -> 1.5502654 | F11: =Annual_Aggregates!D11 -> 1717.5997 | G11: =Annual_Aggregates!E11 -> 0.11062093
A12: C | B12: 10 | C12: C-10kWh | D12: =IFERROR(((Annual_Aggregates!D12-Annual_Aggregates!$D$4)/Annual_Aggregates!$D$4)/((Annual_Aggregates!E12-Annual_Aggregates!$E$4)/Annual_Aggregates!$E$4),"") -> 3.2781832 | E12: =IFERROR(SUMPRODUCT(Monthly_Aggregates!R5:R15,Monthly_Elasticity!J5:J15)/SUM(Monthly_Aggregates!R5:R15),"") -> -0.90879082 | F12: =Annual_Aggregates!D12 -> 1227.1164 | G12: =Annual_Aggregates!E12 -> 0.10203414
A13: C | B13: 15 | C13: C-15kWh | D13: =IFERROR(((Annual_Aggregates!D13-Annual_Aggregates!$D$4)/Annual_Aggregates!$D$4)/((Annual_Aggregates!E13-Annual_Aggregates!$E$4)/Annual_Aggregates!$E$4),"") -> 4.4391142 | E13: =IFERROR(SUMPRODUCT(Monthly_Aggregates!T5:T15,Monthly_Elasticity!K5:K15)/SUM(Monthly_Aggregates!T5:T15),"") -> 0.33558484 | F13: =Annual_Aggregates!D13 -> 1084.5539 | G13: =Annual_Aggregates!E13 -> 0.10126794
A14: C | B14: 20 | C14: C-20kWh | D14: =IFERROR(((Annual_Aggregates!D14-Annual_Aggregates!$D$4)/Annual_Aggregates!$D$4)/((Annual_Aggregates!E14-Annual_Aggregates!$E$4)/Annual_Aggregates!$E$4),"") -> 5.2744758 | E14: =IFERROR(SUMPRODUCT(Monthly_Aggregates!V5:V15,Monthly_Elasticity!L5:L15)/SUM(Monthly_Aggregates!V5:V15),"") -> 3.5912158 | F14: =Annual_Aggregates!D14 -> 997.85948 | G14: =Annual_Aggregates!E14 -> 0.10114259
A15: C | B15: 30 | C15: C-30kWh | D15: =IFERROR(((Annual_Aggregates!D15-Annual_Aggregates!$D$4)/Annual_Aggregates!$D$4)/((Annual_Aggregates!E15-Annual_Aggregates!$E$4)/Annual_Aggregates!$E$4),"") -> 5.2313704 | E15: =IFERROR(SUMPRODUCT(Monthly_Aggregates!X5:X15,Monthly_Elasticity!M5:M15)/SUM(Monthly_Aggregates!X5:X15),"") -> 2.1808154 | F15: =Annual_Aggregates!D15 -> 944.81302 | G15: =Annual_Aggregates!E15 -> 0.10035487

Sheet Charts
A1: Editable Comparative Charts — Elasticity ε
A41: Month | B41: A-10kWh | C41: B-10kWh | D41: C-10kWh
A42: Jan | B42: =Monthly_Elasticity!B4 -> 0 | C42: =Monthly_Elasticity!F4 -> 0 | D42: =Monthly_Elasticity!J4 -> 0
A43: Feb | B43: =Monthly_Elasticity!B5 -> -0.096316943 | C43: =Monthly_Elasticity!F5 -> -0.8394471 | D43: =Monthly_Elasticity!J5 -> -0.99169425
A44: Mar | B44: =Monthly_Elasticity!B6 -> 0.33215669 | C44: =Monthly_Elasticity!F6 -> -0.1450447 | D44: =Monthly_Elasticity!J6 -> -0.038760128
A45: Apr | B45: =Monthly_Elasticity!B7 -> 0.97573945 | C45: =Monthly_Elasticity!F7 -> 1.0076302 | D45: =Monthly_Elasticity!J7 -> 0.73793377
A46: May | B46: =Monthly_Elasticity!B8 -> 22.930942 | C46: =Monthly_Elasticity!F8 -> 3.1061244 | D46: =Monthly_Elasticity!J8 -> 4.8200763
A47: Jun | B47: =Monthly_Elasticity!B9 -> -2.6283105 | C47: =Monthly_Elasticity!F9 -> 16.035319 | D47: =Monthly_Elasticity!J9 -> -34.018185
A48: Jul | B48: =Monthly_Elasticity!B10 -> -0.19472408 | C48: =Monthly_Elasticity!F10 -> -0.13183803 | D48: =Monthly_Elasticity!J10 -> -1.3153163
A49: Aug | B49: =Monthly_Elasticity!B11 -> 0.098935343 | C49: =Monthly_Elasticity!F11 -> -0.23134117 | D49: =Monthly_Elasticity!J11 -> -0.3018434
A50: Sep | B50: =Monthly_Elasticity!B12 -> 2.2513233 | C50: =Monthly_Elasticity!F12 -> 1.2043864 | D50: =Monthly_Elasticity!J12 -> 3.6467536
A51: Oct | B51: =Monthly_Elasticity!B13 -> -0.97069625 | C51: =Monthly_Elasticity!F13 -> -0.30383968 | D51: =Monthly_Elasticity!J13 -> -0.51922184
A52: Nov | B52: =Monthly_Elasticity!B14 -> 4.8864941 | C52: =Monthly_Elasticity!F14 -> 2.9453362 | D52: =Monthly_Elasticity!J14 -> -0.48474833
A53: Dec | B53: =Monthly_Elasticity!B15 -> -217.81533 | C53: =Monthly_Elasticity!F15 -> 58.654884 | D53: =Monthly_Elasticity!J15 -> 9.091928
A56: Month | B56: A-15kWh | C56: B-15kWh | D56: C-15kWh
A57: Jan | B57: =Monthly_Elasticity!C4 -> 0 | C57: =Monthly_Elasticity!G4 -> 0 | D57: =Monthly_Elasticity!K4 -> 0
A58: Feb | B58: =Monthly_Elasticity!C5 -> -0.011864351 | C58: =Monthly_Elasticity!G5 -> -0.74426653 | D58: =Monthly_Elasticity!K5 -> -1.13344
A59: Mar | B59: =Monthly_Elasticity!C6 -> 0.33215669 | C59: =Monthly_Elasticity!G6 -> -0.03506819 | D59: =Monthly_Elasticity!K6 -> 0.24694928
A60: Apr | B60: =Monthly_Elasticity!C7 -> 0.97573945 | C60: =Monthly_Elasticity!G7 -> 1.0449247 | D60: =Monthly_Elasticity!K7 -> 0.86638877
A61: May | B61: =Monthly_Elasticity!C8 -> 22.930942 | C61: =Monthly_Elasticity!G8 -> 3.605657 | D61: =Monthly_Elasticity!K8 -> 9.1712358
A62: Jun | B62: =Monthly_Elasticity!C9 -> -2.6283105 | C62: =Monthly_Elasticity!G9 -> 9.532438 | D62: =Monthly_Elasticity!K9 -> -28.465278
A63: Jul | B63: =Monthly_Elasticity!C10 -> -0.19472408 | C63: =Monthly_Elasticity!G10 -> -0.0098791044 | D63: =Monthly_Elasticity!K10 -> -1.9321077
A64: Aug | B64: =Monthly_Elasticity!C11 -> 0.098935343 | C64: =Monthly_Elasticity!G11 -> -0.18662991 | D64: =Monthly_Elasticity!K11 -> -0.1822122
A65: Sep | B65: =Monthly_Elasticity!C12 -> 2.2513233 | C65: =Monthly_Elasticity!G12 -> 1.2571328 | D65: =Monthly_Elasticity!K12 -> 4.5304239
A66: Oct | B66: =Monthly_Elasticity!C13 -> -0.97069625 | C66: =Monthly_Elasticity!G13 -> -0.66169661 | D66: =Monthly_Elasticity!K13 -> -0.51767046
A67: Nov | B67: =Monthly_Elasticity!C14 -> 4.8864941 | C67: =Monthly_Elasticity!G14 -> 2.3451763 | D67: =Monthly_Elasticity!K14 -> 0.16902231
A68: Dec | B68: =Monthly_Elasticity!C15 -> -217.81533 | C68: =Monthly_Elasticity!G15 -> 11.692287 | D68: =Monthly_Elasticity!K15 -> 10.580759
A71: Month | B71: A-20kWh | C71: B-20kWh | D71: C-20kWh
A72: Jan | B72: =Monthly_Elasticity!D4 -> 0 | C72: =Monthly_Elasticity!H4 -> 0 | D72: =Monthly_Elasticity!L4 -> 0
A73: Feb | B73: =Monthly_Elasticity!D5 -> -0.011864351 | C73: =Monthly_Elasticity!H5 -> -0.69161921 | D73: =Monthly_Elasticity!L5 -> -1.1925348
A74: Mar | B74: =Monthly_Elasticity!D6 -> 0.33215669 | C74: =Monthly_Elasticity!H6 -> 0.16949114 | D74: =Monthly_Elasticity!L6 -> 0.44039092
A75: Apr | B75: =Monthly_Elasticity!D7 -> 0.97573945 | C75: =Monthly_Elasticity!H7 -> 1.0752286 | D75: =Monthly_Elasticity!L7 -> 1.0130246
A76: May | B76: =Monthly_Elasticity!D8 -> 22.930942 | C76: =Monthly_Elasticity!H8 -> 3.4432806 | D76: =Monthly_Elasticity!L8 -> 7.2829116
A77: Jun | B77: =Monthly_Elasticity!D9 -> -2.6283105 | C77: =Monthly_Elasticity!H9 -> -6.5997944 | D77: =Monthly_Elasticity!L9 -> 18.707815
A78: Jul | B78: =Monthly_Elasticity!D10 -> -0.19472408 | C78: =Monthly_Elasticity!H10 -> -0.030661478 | D78: =Monthly_Elasticity!L10 -> -0.42708408
A79: Aug | B79: =Monthly_Elasticity!D11 -> 0.098935343 | C79: =Monthly_Elasticity!H11 -> -0.14557328 | D79: =Monthly_Elasticity!L11 -> 0.41337012
A80: Sep | B80: =Monthly_Elasticity!D12 -> 2.2513233 | C80: =Monthly_Elasticity!H12 -> 1.4562916 | D80: =Monthly_Elasticity!L12 -> 5.8240285
A81: Oct | B81: =Monthly_Elasticity!D13 -> -0.97069625 | C81: =Monthly_Elasticity!H13 -> -0.78045328 | D81: =Monthly_Elasticity!L13 -> -0.30975272
A82: Nov | B82: =Monthly_Elasticity!D14 -> 4.8864941 | C82: =Monthly_Elasticity!H14 -> 2.1464105 | D82: =Monthly_Elasticity!L14 -> -1.339388
A83: Dec | B83: =Monthly_Elasticity!D15 -> -217.81533 | C83: =Monthly_Elasticity!H15 -> 8.7160357 | D83: =Monthly_Elasticity!L15 -> 10.338556
...
