Workbook

Sheet Monthly_PS_to_grid
A1: Month | B1: A-10 | C1: A-15 | D1: A-20 | E1: A-30 | F1: B-10 | G1: B-15 | H1: B-20 | I1: B-30 | J1: C-10 | K1: C-15 | L1: C-20 | M1: C-30
A2: January | B2: 308.63088 | C2: 308.65549 | D2: 308.67973 | E2: 308.72706 | F2: 301.20137 | G2: 293.2462 | H2: 283.9857 | I2: 267.98079 | J2: 293.29456 | K2: 292.88689 | L2: 293.69853 | M2: 294.92064
A3: February | B3: 275.01915 | C3: 275.04444 | D3: 275.06907 | E3: 275.11833 | F3: 278.34287 | G3: 272.41129 | H3: 264.09104 | I3: 251.11991 | J3: 256.02847 | K3: 252.19838 | L3: 252.13176 | M3: 253.47382
A4: March | B4: 289.59178 | C4: 289.62018 | D4: 289.64858 | E4: 289.70539 | F4: 280.67395 | G4: 273.42104 | H4: 266.74351 | I4: 258.45479 | J4: 270.09539 | K4: 270.70136 | L4: 280.17634 | M4: 278.04561
A5: April | B5: 259.5982 | C5: 259.62662 | D5: 259.65503 | E5: 259.71187 | F5: 248.49604 | G5: 241.70854 | H5: 234.30167 | I5: 222.80721 | J5: 245.56796 | K5: 243.27331 | L5: 253.53764 | M5: 259.29469
A6: May | B6: 272.39635 | C6: 272.49227 | D6: 272.52163 | E6: 272.58034 | F6: 262.59888 | G6: 257.54257 | H6: 251.03276 | I6: 241.85266 | J6: 263.39059 | K6: 260.84891 | L6: 261.32678 | M6: 265.28196
A7: June | B7: 249.72784 | C7: 249.75624 | D7: 249.78464 | E7: 249.84145 | F7: 238.46909 | G7: 232.83488 | H7: 227.04418 | I7: 218.59174 | J7: 239.88334 | K7: 237.04745 | L7: 238.70593 | M7: 242.98403
A8: July | B8: 246.94029 | C8: 246.96966 | D8: 246.99902 | E8: 247.05774 | F8: 238.23314 | G8: 230.34773 | H8: 222.67945 | I8: 211.08959 | J8: 235.19127 | K8: 231.04796 | L8: 232.76814 | M8: 238.47538
A9: August | B9: 245.16418 | C9: 245.19353 | D9: 245.22288 | E9: 245.28159 | F9: 235.87479 | G9: 229.76753 | H9: 224.42884 | I9: 214.99076 | J9: 237.68446 | K9: 235.95772 | L9: 257.79034 | M9: 272.54998
A10: September | B10: 259.65067 | C10: 259.67908 | D10: 259.7075 | E10: 259.76432 | F10: 264.9436 | G10: 260.55512 | H10: 254.80016 | I10: 243.60028 | J10: 236.74852 | K10: 246.60573 | L10: 257.97615 | M10: 260.08753
A11: October | B11: 269.79795 | C11: 269.84612 | D11: 269.89429 | E11: 269.99064 | F11: 279.76752 | G11: 273.04774 | H11: 266.35708 | I11: 253.40018 | J11: 243.02215 | K11: 243.98896 | L11: 250.36074 | M11: 253.94137
A12: November | B12: 261.85778 | C12: 261.90282 | D12: 261.94786 | E12: 262.03794 | F12: 255.77593 | G12: 249.81553 | H12: 242.98123 | I12: 231.84001 | J12: 250.70134 | K12: 254.43977 | L12: 255.40893 | M12: 254.9653
A13: December | B13: 303.77262 | C13: 303.81741 | D13: 303.85965 | E13: 303.93991 | F13: 293.51968 | G13: 286.61637 | H13: 278.2017 | I13: 261.61935 | J13: 296.15477 | K13: 296.06683 | L13: 296.52804 | M13: 295.51563
A14: Annual | B14: 3242.1477 | C14: 3242.6039 | D14: 3242.9899 | E14: 3243.7566 | F14: 3177.8969 | G14: 3101.3145 | H14: 3016.6473 | I14: 2877.3473 | J14: 3067.7628 | K14: 3065.0633 | L14: 3130.4093 | M14: 3169.5359

Sheet PS_to_grid_Charts
A1: Monthly PS_to_grid (€): Comparisons by Strategy and Battery Capacity
A3: Month | B3: A-10 | C3: A-15 | D3: A-20 | E3: A-30 | H3: Month | I3: B-10 | J3: B-15 | K3: B-20 | L3: B-30
A4: January | B4: =Monthly_PS_to_grid!B2 -> 308.63088 | C4: =Monthly_PS_to_grid!C2 -> 308.65549 | D4: =Monthly_PS_to_grid!D2 -> 308.67973 | E4: =Monthly_PS_to_grid!E2 -> 308.72706 | H4: January | I4: =Monthly_PS_to_grid!F2 -> 301.20137 | J4: =Monthly_PS_to_grid!G2 -> 293.2462 | K4: =Monthly_PS_to_grid!H2 -> 283.9857 | L4: =Monthly_PS_to_grid!I2 -> 267.98079
A5: February | B5: =Monthly_PS_to_grid!B3 -> 275.01915 | C5: =Monthly_PS_to_grid!C3 -> 275.04444 | D5: =Monthly_PS_to_grid!D3 -> 275.06907 | E5: =Monthly_PS_to_grid!E3 -> 275.11833 | H5: February | I5: =Monthly_PS_to_grid!F3 -> 278.34287 | J5: =Monthly_PS_to_grid!G3 -> 272.41129 | K5: =Monthly_PS_to_grid!H3 -> 264.09104 | L5: =Monthly_PS_to_grid!I3 -> 251.11991
A6: March | B6: =Monthly_PS_to_grid!B4 -> 289.59178 | C6: =Monthly_PS_to_grid!C4 -> 289.62018 | D6: =Monthly_PS_to_grid!D4 -> 289.64858 | E6: =Monthly_PS_to_grid!E4 -> 289.70539 | H6: March | I6: =Monthly_PS_to_grid!F4 -> 280.67395 | J6: =Monthly_PS_to_grid!G4 -> 273.42104 | K6: =Monthly_PS_to_grid!H4 -> 266.74351 | L6: =Monthly_PS_to_grid!I4 -> 258.45479
A7: April | B7: =Monthly_PS_to_grid!B5 -> 259.5982 | C7: =Monthly_PS_to_grid!C5 -> 259.62662 | D7: =Monthly_PS_to_grid!D5 -> 259.65503 | E7: =Monthly_PS_to_grid!E5 -> 259.71187 | H7: April | I7: =Monthly_PS_to_grid!F5 -> 248.49604 | J7: =Monthly_PS_to_grid!G5 -> 241.70854 | K7: =Monthly_PS_to_grid!H5 -> 234.30167 | L7: =Monthly_PS_to_grid!I5 -> 222.80721
A8: May | B8: =Monthly_PS_to_grid!B6 -> 272.39635 | C8: =Monthly_PS_to_grid!C6 -> 272.49227 | D8: =Monthly_PS_to_grid!D6 -> 272.52163 | E8: =Monthly_PS_to_grid!E6 -> 272.58034 | H8: May | I8: =Monthly_PS_to_grid!F6 -> 262.59888 | J8: =Monthly_PS_to_grid!G6 -> 257.54257 | K8: =Monthly_PS_to_grid!H6 -> 251.03276 | L8: =Monthly_PS_to_grid!I6 -> 241.85266
A9: June | B9: =Monthly_PS_to_grid!B7 -> 249.72784 | C9: =Monthly_PS_to_grid!C7 -> 249.75624 | D9: =Monthly_PS_to_grid!D7 -> 249.78464 | E9: =Monthly_PS_to_grid!E7 -> 249.84145 | H9: June | I9: =Monthly_PS_to_grid!F7 -> 238.46909 | J9: =Monthly_PS_to_grid!G7 -> 232.83488 | K9: =Monthly_PS_to_grid!H7 -> 227.04418 | L9: =Monthly_PS_to_grid!I7 -> 218.59174
A10: July | B10: =Monthly_PS_to_grid!B8 -> 246.94029 | C10: =Monthly_PS_to_grid!C8 -> 246.96966 | D10: =Monthly_PS_to_grid!D8 -> 246.99902 | E10: =Monthly_PS_to_grid!E8 -> 247.05774 | H10: July | I10: =Monthly_PS_to_grid!F8 -> 238.23314 | J10: =Monthly_PS_to_grid!G8 -> 230.34773 | K10: =Monthly_PS_to_grid!H8 -> 222.67945 | L10: =Monthly_PS_to_grid!I8 -> 211.08959
A11: August | B11: =Monthly_PS_to_grid!B9 -> 245.16418 | C11: =Monthly_PS_to_grid!C9 -> 245.19353 | D11: =Monthly_PS_to_grid!D9 -> 245.22288 | E11: =Monthly_PS_to_grid!E9 -> 245.28159 | H11: August | I11: =Monthly_PS_to_grid!F9 -> 235.87479 | J11: =Monthly_PS_to_grid!G9 -> 229.76753 | K11: =Monthly_PS_to_grid!H9 -> 224.42884 | L11: =Monthly_PS_to_grid!I9 -> 214.99076
A12: September | B12: =Monthly_PS_to_grid!B10 -> 259.65067 | C12: =Monthly_PS_to_grid!C10 -> 259.67908 | D12: =Monthly_PS_to_grid!D10 -> 259.7075 | E12: =Monthly_PS_to_grid!E10 -> 259.76432 | H12: September | I12: =Monthly_PS_to_grid!F10 -> 264.9436 | J12: =Monthly_PS_to_grid!G10 -> 260.55512 | K12: =Monthly_PS_to_grid!H10 -> 254.80016 | L12: =Monthly_PS_to_grid!I10 -> 243.60028
A13: October | B13: =Monthly_PS_to_grid!B11 -> 269.79795 | C13: =Monthly_PS_to_grid!C11 -> 269.84612 | D13: =Monthly_PS_to_grid!D11 -> 269.89429 | E13: =Monthly_PS_to_grid!E11 -> 269.99064 | H13: October | I13: =Monthly_PS_to_grid!F11 -> 279.76752 | J13: =Monthly_PS_to_grid!G11 -> 273.04774 | K13: =Monthly_PS_to_grid!H11 -> 266.35708 | L13: =Monthly_PS_to_grid!I11 -> 253.40018
A14: November | B14: =Monthly_PS_to_grid!B12 -> 261.85778 | C14: =Monthly_PS_to_grid!C12 -> 261.90282 | D14: =Monthly_PS_to_grid!D12 -> 261.94786 | E14: =Monthly_PS_to_grid!E12 -> 262.03794 | H14: November | I14: =Monthly_PS_to_grid!F12 -> 255.77593 | J14: =Monthly_PS_to_grid!G12 -> 249.81553 | K14: =Monthly_PS_to_grid!H12 -> 242.98123 | L14: =Monthly_PS_to_grid!I12 -> 231.84001
A15: December | B15: =Monthly_PS_to_grid!B13 -> 303.77262 | C15: =Monthly_PS_to_grid!C13 -> 303.81741 | D15: =Monthly_PS_to_grid!D13 -> 303.85965 | E15: =Monthly_PS_to_grid!E13 -> 303.93991 | H15: December | I15: =Monthly_PS_to_grid!F13 -> 293.51968 | J15: =Monthly_PS_to_grid!G13 -> 286.61637 | K15: =Monthly_PS_to_grid!H13 -> 278.2017 | L15: =Monthly_PS_to_grid!I13 -> 261.61935
A20: Month | B20: C-10 | C20: C-15 | D20: C-20 | E20: C-30 | H20: Month | I20: A-10 | J20: B-10 | K20: C-10
A21: January | B21: =Monthly_PS_to_grid!J2 -> 293.29456 | C21: =Monthly_PS_to_grid!K2 -> 292.88689 | D21: =Monthly_PS_to_grid!L2 -> 293.69853 | E21: =Monthly_PS_to_grid!M2 -> 294.92064 | H21: January | I21: =Monthly_PS_to_grid!B2 -> 308.63088 | J21: =Monthly_PS_to_grid!F2 -> 301.20137 | K21: =Monthly_PS_to_grid!J2 -> 293.29456
A22: February | B22: =Monthly_PS_to_grid!J3 -> 256.02847 | C22: =Monthly_PS_to_grid!K3 -> 252.19838 | D22: =Monthly_PS_to_grid!L3 -> 252.13176 | E22: =Monthly_PS_to_grid!M3 -> 253.47382 | H22: February | I22: =Monthly_PS_to_grid!B3 -> 275.01915 | J22: =Monthly_PS_to_grid!F3 -> 278.34287 | K22: =Monthly_PS_to_grid!J3 -> 256.02847
A23: March | B23: =Monthly_PS_to_grid!J4 -> 270.09539 | C23: =Monthly_PS_to_grid!K4 -> 270.70136 | D23: =Monthly_PS_to_grid!L4 -> 280.17634 | E23: =Monthly_PS_to_grid!M4 -> 278.04561 | H23: March | I23: =Monthly_PS_to_grid!B4 -> 289.59178 | J23: =Monthly_PS_to_grid!F4 -> 280.67395 | K23: =Monthly_PS_to_grid!J4 -> 270.09539
A24: April | B24: =Monthly_PS_to_grid!J5 -> 245.56796 | C24: =Monthly_PS_to_grid!K5 -> 243.27331 | D24: =Monthly_PS_to_grid!L5 -> 253.53764 | E24: =Monthly_PS_to_grid!M5 -> 259.29469 | H24: April | I24: =Monthly_PS_to_grid!B5 -> 259.5982 | J24: =Monthly_PS_to_grid!F5 -> 248.49604 | K24: =Monthly_PS_to_grid!J5 -> 245.56796
A25: May | B25: =Monthly_PS_to_grid!J6 -> 263.39059 | C25: =Monthly_PS_to_grid!K6 -> 260.84891 | D25: =Monthly_PS_to_grid!L6 -> 261.32678 | E25: =Monthly_PS_to_grid!M6 -> 265.28196 | H25: May | I25: =Monthly_PS_to_grid!B6 -> 272.39635 | J25: =Monthly_PS_to_grid!F6 -> 262.59888 | K25: =Monthly_PS_to_grid!J6 -> 263.39059
A26: June | B26: =Monthly_PS_to_grid!J7 -> 239.88334 | C26: =Monthly_PS_to_grid!K7 -> 237.04745 | D26: =Monthly_PS_to_grid!L7 -> 238.70593 | E26: =Monthly_PS_to_grid!M7 -> 242.98403 | H26: June | I26: =Monthly_PS_to_grid!B7 -> 249.72784 | J26: =Monthly_PS_to_grid!F7 -> 238.46909 | K26: =Monthly_PS_to_grid!J7 -> 239.88334
A27: July | B27: =Monthly_PS_to_grid!J8 -> 235.19127 | C27: =Monthly_PS_to_grid!K8 -> 231.04796 | D27: =Monthly_PS_to_grid!L8 -> 232.76814 | E27: =Monthly_PS_to_grid!M8 -> 238.47538 | H27: July | I27: =Monthly_PS_to_grid!B8 -> 246.94029 | J27: =Monthly_PS_to_grid!F8 -> 238.23314 | K27: =Monthly_PS_to_grid!J8 -> 235.19127
A28: August | B28: =Monthly_PS_to_grid!J9 -> 237.68446 | C28: =Monthly_PS_to_grid!K9 -> 235.95772 | D28: =Monthly_PS_to_grid!L9 -> 257.79034 | E28: =Monthly_PS_to_grid!M9 -> 272.54998 | H28: August | I28: =Monthly_PS_to_grid!B9 -> 245.16418 | J28: =Monthly_PS_to_grid!F9 -> 235.87479 | K28: =Monthly_PS_to_grid!J9 -> 237.68446
A29: September | B29: =Monthly_PS_to_grid!J10 -> 236.74852 | C29: =Monthly_PS_to_grid!K10 -> 246.60573 | D29: =Monthly_PS_to_grid!L10 -> 257.97615 | E29: =Monthly_PS_to_grid!M10 -> 260.08753 | H29: September | I29: =Monthly_PS_to_grid!B10 -> 259.65067 | J29: =Monthly_PS_to_grid!F10 -> 264.9436 | K29: =Monthly_PS_to_grid!J10 -> 236.74852
A30: October | B30: =Monthly_PS_to_grid!J11 -> 243.02215 | C30: =Monthly_PS_to_grid!K11 -> 243.98896 | D30: =Monthly_PS_to_grid!L11 -> 250.36074 | E30: =Monthly_PS_to_grid!M11 -> 253.94137 | H30: October | I30: =Monthly_PS_to_grid!B11 -> 269.79795 | J30: =Monthly_PS_to_grid!F11 -> 279.76752 | K30: =Monthly_PS_to_grid!J11 -> 243.02215
A31: November | B31: =Monthly_PS_to_grid!J12 -> 250.70134 | C31: =Monthly_PS_to_grid!K12 -> 254.43977 | D31: =Monthly_PS_to_grid!L12 -> 255.40893 | E31: =Monthly_PS_to_grid!M12 -> 254.9653 | H31: November | I31: =Monthly_PS_to_grid!B12 -> 261.85778 | J31: =Monthly_PS_to_grid!F12 -> 255.77593 | K31: =Monthly_PS_to_grid!J12 -> 250.70134
A32: December | B32: =Monthly_PS_to_grid!J13 -> 296.15477 | C32: =Monthly_PS_to_grid!K13 -> 296.06683 | D32: =Monthly_PS_to_grid!L13 -> 296.52804 | E32: =Monthly_PS_to_grid!M13 -> 295.51563 | H32: December | I32: =Monthly_PS_to_grid!B13 -> 303.77262 | J32: =Monthly_PS_to_grid!F13 -> 293.51968 | K32: =Monthly_PS_to_grid!J13 -> 296.15477
A37: Month | B37: A-15 | C37: B-15 | D37: C-15 | H37: Month | I37: A-20 | J37: B-20 | K37: C-20
A38: January | B38: =Monthly_PS_to_grid!C2 -> 308.65549 | C38: =Monthly_PS_to_grid!G2 -> 293.2462 | D38: =Monthly_PS_to_grid!K2 -> 292.88689 | H38: January | I38: =Monthly_PS_to_grid!D2 -> 308.67973 | J38: =Monthly_PS_to_grid!H2 -> 283.9857 | K38: =Monthly_PS_to_grid!L2 -> 293.69853
A39: February | B39: =Monthly_PS_to_grid!C3 -> 275.04444 | C39: =Monthly_PS_to_grid!G3 -> 272.41129 | D39: =Monthly_PS_to_grid!K3 -> 252.19838 | H39: February | I39: =Monthly_PS_to_grid!D3 -> 275.06907 | J39: =Monthly_PS_to_grid!H3 -> 264.09104 | K39: =Monthly_PS_to_grid!L3 -> 252.13176
A40: March | B40: =Monthly_PS_to_grid!C4 -> 289.62018 | C40: =Monthly_PS_to_grid!G4 -> 273.42104 | D40: =Monthly_PS_to_grid!K4 -> 270.70136 | H40: March | I40: =Monthly_PS_to_grid!D4 -> 289.64858 | J40: =Monthly_PS_to_grid!H4 -> 266.74351 | K40: =Monthly_PS_to_grid!L4 -> 280.17634
A41: April | B41: =Monthly_PS_to_grid!C5 -> 259.62662 | C41: =Monthly_PS_to_grid!G5 -> 241.70854 | D41: =Monthly_PS_to_grid!K5 -> 243.27331 | H41: April | I41: =Monthly_PS_to_grid!D5 -> 259.65503 | J41: =Monthly_PS_to_grid!H5 -> 234.30167 | K41: =Monthly_PS_to_grid!L5 -> 253.53764
A42: May | B42: =Monthly_PS_to_grid!C6 -> 272.49227 | C42: =Monthly_PS_to_grid!G6 -> 257.54257 | D42: =Monthly_PS_to_grid!K6 -> 260.84891 | H42: May | I42: =Monthly_PS_to_grid!D6 -> 272.52163 | J42: =Monthly_PS_to_grid!H6 -> 251.03276 | K42: =Monthly_PS_to_grid!L6 -> 261.32678
A43: June | B43: =Monthly_PS_to_grid!C7 -> 249.75624 | C43: =Monthly_PS_to_grid!G7 -> 232.83488 | D43: =Monthly_PS_to_grid!K7 -> 237.04745 | H43: June | I43: =Monthly_PS_to_grid!D7 -> 249.78464 | J43: =Monthly_PS_to_grid!H7 -> 227.04418 | K43: =Monthly_PS_to_grid!L7 -> 238.70593
A44: July | B44: =Monthly_PS_to_grid!C8 -> 246.96966 | C44: =Monthly_PS_to_grid!G8 -> 230.34773 | D44: =Monthly_PS_to_grid!K8 -> 231.04796 | H44: July | I44: =Monthly_PS_to_grid!D8 -> 246.99902 | J44: =Monthly_PS_to_grid!H8 -> 222.67945 | K44: =Monthly_PS_to_grid!L8 -> 232.76814
A45: August | B45: =Monthly_PS_to_grid!C9 -> 245.19353 | C45: =Monthly_PS_to_grid!G9 -> 229.76753 | D45: =Monthly_PS_to_grid!K9 -> 235.95772 | H45: August | I45: =Monthly_PS_to_grid!D9 -> 245.22288 | J45: =Monthly_PS_to_grid!H9 -> 224.42884 | K45: =Monthly_PS_to_grid!L9 -> 257.79034
A46: September | B46: =Monthly_PS_to_grid!C10 -> 259.67908 | C46: =Monthly_PS_to_grid!G10 -> 260.55512 | D46: =Monthly_PS_to_grid!K10 -> 246.60573 | H46: September | I46: =Monthly_PS_to_grid!D10 -> 259.7075 | J46: =Monthly_PS_to_grid!H10 -> 254.80016 | K46: =Monthly_PS_to_grid!L10 -> 257.97615
A47: October | B47: =Monthly_PS_to_grid!C11 -> 269.84612 | C47: =Monthly_PS_to_grid!G11 -> 273.04774 | D47: =Monthly_PS_to_grid!K11 -> 243.98896 | H47: October | I47: =Monthly_PS_to_grid!D11 -> 269.89429 | J47: =Monthly_PS_to_grid!H11 -> 266.35708 | K47: =Monthly_PS_to_grid!L11 -> 250.36074
A48: November | B48: =Monthly_PS_to_grid!C12 -> 261.90282 | C48: =Monthly_PS_to_grid!G12 -> 249.81553 | D48: =Monthly_PS_to_grid!K12 -> 254.43977 | H48: November | I48: =Monthly_PS_to_grid!D12 -> 261.94786 | J48: =Monthly_PS_to_grid!H12 -> 242.98123 | K48: =Monthly_PS_to_grid!L12 -> 255.40893
A49: December | B49: =Monthly_PS_to_grid!C13 -> 303.81741 | C49: =Monthly_PS_to_grid!G13 -> 286.61637 | D49: =Monthly_PS_to_grid!K13 -> 296.06683 | H49: December | I49: =Monthly_PS_to_grid!D13 -> 303.85965 | J49: =Monthly_PS_to_grid!H13 -> 278.2017 | K49: =Monthly_PS_to_grid!L13 -> 296.52804
...
